Workbook
Name magicnums: magicnums!$B$2:$B$18
Name magicvals: magicnums!$A$2:$A$18

Sheet start_points
A1: LOC | B1: LAT | C1: LON | D1: ALT | F1: NOTE | G1: DICT | H1: =start_points!A1 & ", " & start_points!B1 & ", " & start_points!C1 & "," -> LOC, LAT, LON,
A2: K | B2: 38.892751 | C2: -77.051444 | D2: 28.76 | G2: ="'" & start_points!A2 & "': (" & start_points!B2 & ", " & start_points!C2 & ")," -> 'K': (38.892751, -77.051444), | H2: =start_points!A2 & ", " & start_points!B2 & ", " & start_points!C2 & "," -> K, 38.892751, -77.051444,
A3: B | B3: 38.892751 | C3: -77.008885 | D3: 60 | G3: ="'" & start_points!A3 & "': (" & start_points!B3 & ", " & start_points!C3 & ")," -> 'B': (38.892751, -77.008885), | H3: =start_points!A3 & ", " & start_points!B3 & ", " & start_points!C3 & "," -> B, 38.892751, -77.008885,
A4: M | B4: 38.889442 | C4: -77.035252 | D4: 40.18 | G4: ="'" & start_points!A4 & "': (" & start_points!B4 & ", " & start_points!C4 & ")," -> 'M': (38.889442, -77.035252), | H4: =start_points!A4 & ", " & start_points!B4 & ", " & start_points!C4 & "," -> M, 38.889442, -77.035252,
A5: J | B5: 38.889801 | C5: -77.036569 | D5: 22.39 | G5: ="'" & start_points!A5 & "': (" & start_points!B5 & ", " & start_points!C5 & ")," -> 'J': (38.8898013, -77.0365691), | H5: =start_points!A5 & ", " & start_points!B5 & ", " & start_points!C5 & "," -> J, 38.8898013, -77.0365691,
A6: Hk | B6: 38.895137 | C6: -77.051444 | D6: 96.77 | G6: ="'" & start_points!A7 & "': (" & start_points!B7 & ", " & start_points!C7 & ")," -> 'P': (38.8710236, -77.0559852), | H6: =start_points!A7 & ", " & start_points!B7 & ", " & start_points!C7 & "," -> P, 38.8710236, -77.0559852,
A7: P | B7: 38.871024 | C7: -77.055985 | D7: 18

Sheet trypoints
A1: LOC | B1: LAT | C1: LON | D1: ALT
A2: K | B2: 38.892751 | C2: -77.051444 | D2: 29
A3: B | B3: 38.892751 | C3: -77.008885 | D3: 60
A4: M | B4: 38.889442 | C4: -77.035252 | D4: 40
A5: J | B5: 38.889801 | C5: -77.036569 | D5: 22
A6: Hk | B6: 38.895137 | C6: -77.051444 | D6: 97
A7: P | B7: 38.871024 | C7: -77.055985 | D7: 18
A8: Nb | B8: 38.995957 | C8: -77.040986 | D8: 259
A9: Sb | B9: 38.790339 | C9: -77.040586 | D9: 1
A10: Wb | B10: 38.893245 | C10: -77.172301 | D10: 343
A11: Eb | B11: 38.89286 | C11: -76.909166 | D11: 94
A12: Nc | B12: 38.893596 | C12: -77.040986 | D12: 15
A13: Sc | B13: 38.8927 | C13: -77.040586 | D13: 15
... A23: AN | B23: 38.918583 | C23: -76.941922 | D23: 0

Sheet pairs
A1: Refpnt | B1: Pnt | C1: Az | D1: Back | E1: Dist | F1: Feet | G1: Az* | H1: Back* | I1: Bold | J1: Italic
A2: Wc | B2: Ac | D2: 343.74 | E2: 0.005125 | F2: =pairs[[#This Row],[ Dist]]*5280 -> 27.06 | G2: =ROUND(pairs[[#This Row],[ Az]]-ROUNDDOWN(pairs[[#This Row],[ Az]],0),1) -> 0 | H2: =ROUND(pairs[[#This Row],[ Back]]-ROUNDDOWN(pairs[[#This Row],[ Back]],0),1) -> 0.7 | I2: =IF( OR( OR(pairs[[#This Row],[Az*]]=0, pairs[[#This Row],[Back*]]=0), OR(pairs[[#This Row],[Az*]]=1, pairs[[#This Row],[Back*]]=1)), 1, 0) -> 1 | J2: =IF(OR(pairs[[#This Row],[Az*]]=0.5,pairs[[#This Row],[Back*]]=0.5),1,0) -> 0
A3: Wc | B3: AN | D3: 251.75 | E3: 5.597033 | F3: =pairs[[#This Row],[ Dist]]*5280 -> 29552.334 | G3: =ROUND(pairs[[#This Row],[ Az]]-ROUNDDOWN(pairs[[#This Row],[ Az]],0),1) -> 0 | H3: =ROUND(pairs[[#This Row],[ Back]]-ROUNDDOWN(pairs[[#This Row],[ Back]],0),1) -> 0.8 | I3: =IF( OR( OR(pairs[[#This Row],[Az*]]=0, pairs[[#This Row],[Back*]]=0), OR(pairs[[#This Row],[Az*]]=1, pairs[[#This Row],[Back*]]=1)), 1, 0) -> 1 | J3: =IF(OR(pairs[[#This Row],[Az*]]=0.5,pairs[[#This Row],[Back*]]=0.5),1,0) -> 0
A4: Wc | B4: B | D4: 270.98 | E4: 1.715463 | F4: =pairs[[#This Row],[ Dist]]*5280 -> 9057.6446 | G4: =ROUND(pairs[[#This Row],[ Az]]-ROUNDDOWN(pairs[[#This Row],[ Az]],0),1) -> 0 | H4: =ROUND(pairs[[#This Row],[ Back]]-ROUNDDOWN(pairs[[#This Row],[ Back]],0),1) -> 1 | I4: =IF( OR( OR(pairs[[#This Row],[Az*]]=0, pairs[[#This Row],[Back*]]=0), OR(pairs[[#This Row],[Az*]]=1, pairs[[#This Row],[Back*]]=1)), 1, 0) -> 1 | J4: =IF(OR(pairs[[#This Row],[Az*]]=0.5,pairs[[#This Row],[Back*]]=0.5),1,0) -> 0
A5: Wc | B5: Eb | D5: 270.22 | E5: 7.076808 | F5: =pairs[[#This Row],[ Dist]]*5280 -> 37365.546 | G5: =ROUND(pairs[[#This Row],[ Az]]-ROUNDDOWN(pairs[[#This Row],[ Az]],0),1) -> 0 | H5: =ROUND(pairs[[#This Row],[ Back]]-ROUNDDOWN(pairs[[#This Row],[ Back]],0),1) -> 0.2 | I5: =IF( OR( OR(pairs[[#This Row],[Az*]]=0, pairs[[#This Row],[Back*]]=0), OR(pairs[[#This Row],[Az*]]=1, pairs[[#This Row],[Back*]]=1)), 1, 0) -> 1 | J5: =IF(OR(pairs[[#This Row],[Az*]]=0.5,pairs[[#This Row],[Back*]]=0.5),1,0) -> 0
A6: Wc | B6: Ec | D6: 347.83 | E6: 0.027184 | F6: =pairs[[#This Row],[ Dist]]*5280 -> 143.53152 | G6: =ROUND(pairs[[#This Row],[ Az]]-ROUNDDOWN(pairs[[#This Row],[ Az]],0),1) -> 0 | H6: =ROUND(pairs[[#This Row],[ Back]]-ROUNDDOWN(pairs[[#This Row],[ Back]],0),1) -> 0.8 | I6: =IF( OR( OR(pairs[[#This Row],[Az*]]=0, pairs[[#This Row],[Back*]]=0), OR(pairs[[#This Row],[Az*]]=1, pairs[[#This Row],[Back*]]=1)), 1, 0) -> 1 | J6: =IF(OR(pairs[[#This Row],[Az*]]=0.5,pairs[[#This Row],[Back*]]=0.5),1,0) -> 0
A7: Wc | B7: HawC | D7: 279.28 | E7: 1.771883 | F7: =pairs[[#This Row],[ Dist]]*5280 -> 9355.5422 | G7: =ROUND(pairs[[#This Row],[ Az]]-ROUNDDOWN(pairs[[#This Row],[ Az]],0),1) -> 0 | H7: =ROUND(pairs[[#This Row],[ Back]]-ROUNDDOWN(pairs[[#This Row],[ Back]],0),1) -> 0.3 | I7: =IF( OR( OR(pairs[[#This Row],[Az*]]=0, pairs[[#This Row],[Back*]]=0), OR(pairs[[#This Row],[Az*]]=1, pairs[[#This Row],[Back*]]=1)), 1, 0) -> 1 | J7: =IF(OR(pairs[[#This Row],[Az*]]=0.5,pairs[[#This Row],[Back*]]=0.5),1,0) -> 0
A8: Wc | B8: HawK | D8: 84.68 | E8: 0.541057 | F8: =pairs[[#This Row],[ Dist]]*5280 -> 2856.781 | G8: =ROUND(pairs[[#This Row],[ Az]]-ROUNDDOWN(pairs[[#This Row],[ Az]],0),1) -> 0 | H8: =ROUND(pairs[[#This Row],[ Back]]-ROUNDDOWN(pairs[[#This Row],[ Back]],0),1) -> 0.7 | I8: =IF( OR( OR(pairs[[#This Row],[Az*]]=0, pairs[[#This Row],[Back*]]=0), OR(pairs[[#This Row],[Az*]]=1, pairs[[#This Row],[Back*]]=1)), 1, 0) -> 1 | J8: =IF(OR(pairs[[#This Row],[Az*]]=0.5,pairs[[#This Row],[Back*]]=0.5),1,0) -> 0
A9: Wc | B9: HawW | D9: 228.41 | E9: 0.422556 | F9: =pairs[[#This Row],[ Dist]]*5280 -> 2231.0957 | G9: =ROUND(pairs[[#This Row],[ Az]]-ROUNDDOWN(pairs[[#This Row],[ Az]],0),1) -> 0 | H9: =ROUND(pairs[[#This Row],[ Back]]-ROUNDDOWN(pairs[[#This Row],[ Back]],0),1) -> 0.4 | I9: =IF( OR( OR(pairs[[#This Row],[Az*]]=0, pairs[[#This Row],[Back*]]=0), OR(pairs[[#This Row],[Az*]]=1, pairs[[#This Row],[Back*]]=1)), 1, 0) -> 1 | J9: =IF(OR(pairs[[#This Row],[Az*]]=0.5,pairs[[#This Row],[Back*]]=0.5),1,0) -> 0
A10: Wc | B10: Hk | D10: 103.33 | E10: 0.588882 | F10: =pairs[[#This Row],[ Dist]]*5280 -> 3109.297 | G10: =ROUND(pairs[[#This Row],[ Az]]-ROUNDDOWN(pairs[[#This Row],[ Az]],0),1) -> 0 | H10: =ROUND(pairs[[#This Row],[ Back]]-ROUNDDOWN(pairs[[#This Row],[ Back]],0),1) -> 0.3 | I10: =IF( OR( OR(pairs[[#This Row],[Az*]]=0, pairs[[#This Row],[Back*]]=0), OR(pairs[[#This Row],[Az*]]=1, pairs[[#This Row],[Back*]]=1)), 1, 0) -> 1 | J10: =IF(OR(pairs[[#This Row],[Az*]]=0.5,pairs[[#This Row],[Back*]]=0.5),1,0) -> 0
A11: Wc | B11: J | D11: 315.76 | E11: 0.32498 | F11: =pairs[[#This Row],[ Dist]]*5280 -> 1715.8944 | G11: =ROUND(pairs[[#This Row],[ Az]]-ROUNDDOWN(pairs[[#This Row],[ Az]],0),1) -> 0 | H11: =ROUND(pairs[[#This Row],[ Back]]-ROUNDDOWN(pairs[[#This Row],[ Back]],0),1) -> 0.8 | I11: =IF( OR( OR(pairs[[#This Row],[Az*]]=0, pairs[[#This Row],[Back*]]=0), OR(pairs[[#This Row],[Az*]]=1, pairs[[#This Row],[Back*]]=1)), 1, 0) -> 1 | J11: =IF(OR(pairs[[#This Row],[Az*]]=0.5,pairs[[#This Row],[Back*]]=0.5),1,0) -> 0
A12: Wc | B12: K | D12: 87.1 | E12: 0.573765 | F12: =pairs[[#This Row],[ Dist]]*5280 -> 3029.4792 | G12: =ROUND(pairs[[#This Row],[ Az]]-ROUNDDOWN(pairs[[#This Row],[ Az]],0),1) -> 0 | H12: =ROUND(pairs[[#This Row],[ Back]]-ROUNDDOWN(pairs[[#This Row],[ Back]],0),1) -> 0.1 | I12: =IF( OR( OR(pairs[[#This Row],[Az*]]=0, pairs[[#This Row],[Back*]]=0), OR(pairs[[#This Row],[Az*]]=1, pairs[[#This Row],[Back*]]=1)), 1, 0) -> 1 | J12: =IF(OR(pairs[[#This Row],[Az*]]=0.5,pairs[[#This Row],[Back*]]=0.5),1,0) -> 0
A13: Wc | B13: M | D13: 310.89 | E13: 0.393593 | F13: =pairs[[#This Row],[ Dist]]*5280 -> 2078.171 | G13: =ROUND(pairs[[#This Row],[ Az]]-ROUNDDOWN(pairs[[#This Row],[ Az]],0),1) -> 0 | H13: =ROUND(pairs[[#This Row],[ Back]]-ROUNDDOWN(pairs[[#This Row],[ Back]],0),1) -> 0.9 | I13: =IF( OR( OR(pairs[[#This Row],[Az*]]=0, pairs[[#This Row],[Back*]]=0), OR(pairs[[#This Row],[Az*]]=1, pairs[[#This Row],[Back*]]=1)), 1, 0) -> 1 | J13: =IF(OR(pairs[[#This Row],[Az*]]=0.5,pairs[[#This Row],[Back*]]=0.5),1,0) -> 0
... A22: Wc | B22: Wb | D22: 90 | E22: 7.071068 | F22: =pairs[[#This Row],[ Dist]]*5280 -> 37335.239 | G22: =ROUND(pairs[[#This Row],[ Az]]-ROUNDDOWN(pairs[[#This Row],[ Az]],0),1) -> 0 | H22: =ROUND(pairs[[#This Row],[ Back]]-ROUNDDOWN(pairs[[#This Row],[ Back]],0),1) -> 0 | I22: =IF( OR( OR(pairs[[#This Row],[Az*]]=0, pairs[[#This Row],[Back*]]=0), OR(pairs[[#This Row],[Az*]]=1, pairs[[#This Row],[Back*]]=1)), 1, 0) -> 1 | J22: =IF(OR(pairs[[#This Row],[Az*]]=0.5,pairs[[#This Row],[Back*]]=0.5),1,0) -> 0
A23: Wb | B23: Ac | D23: 270.12 | E23: 7.072512 | F23: =pairs[[#This Row],[ Dist]]*5280 -> 37342.863 | G23: =ROUND(pairs[[#This Row],[ Az]]-ROUNDDOWN(pairs[[#This Row],[ Az]],0),1) -> 0 | H23: =ROUND(pairs[[#This Row],[ Back]]-ROUNDDOWN(pairs[[#This Row],[ Back]],0),1) -> 0.1 | I23: 0 | J23: =IF(OR(pairs[[#This Row],[Az*]]=0.5,pairs[[#This Row],[Back*]]=0.5),1,0) -> 0
A24: Wb | B24: AN | D24: 262.03 | E24: 12.5075 | F24: =pairs[[#This Row],[ Dist]]*5280 -> 66039.6 | G24: =ROUND(pairs[[#This Row],[ Az]]-ROUNDDOWN(pairs[[#This Row],[ Az]],0),1) -> 0 | H24: =ROUND(pairs[[#This Row],[ Back]]-ROUNDDOWN(pairs[[#This Row],[ Back]],0),1) -> 0 | I24: =IF( OR( OR(pairs[[#This Row],[Az*]]=0, pairs[[#This Row],[Back*]]=0), OR(pairs[[#This Row],[Az*]]=1, pairs[[#This Row],[Back*]]=1)), 1, 0) -> 1 | J24: =IF(OR(pairs[[#This Row],[Az*]]=0.5,pairs[[#This Row],[Back*]]=0.5),1,0) -> 0
A25: Wb | B25: B | D25: 270.27 | E25: 8.786369 | F25: =pairs[[#This Row],[ Dist]]*5280 -> 46392.028 | G25: =ROUND(pairs[[#This Row],[ Az]]-ROUNDDOWN(pairs[[#This Row],[ Az]],0),1) -> 0 | H25: =ROUND(pairs[[#This Row],[ Back]]-ROUNDDOWN(pairs[[#This Row],[ Back]],0),1) -> 0.3 | I25: =IF( OR( OR(pairs[[#This Row],[Az*]]=0, pairs[[#This Row],[Back*]]=0), OR(pairs[[#This Row],[Az*]]=1, pairs[[#This Row],[Back*]]=1)), 1, 0) -> 1 | J25: =IF(OR(pairs[[#This Row],[Az*]]=0.5,pairs[[#This Row],[Back*]]=0.5),1,0) -> 0
A26: Wb | B26: Eb | D26: 270.19 | E26: 14.147874 | F26: =pairs[[#This Row],[ Dist]]*5280 -> 74700.775 | G26: =ROUND(pairs[[#This Row],[ Az]]-ROUNDDOWN(pairs[[#This Row],[ Az]],0),1) -> 0 | H26: =ROUND(pairs[[#This Row],[ Back]]-ROUNDDOWN(pairs[[#This Row],[ Back]],0),1) -> 0.2 | I26: =IF( OR( OR(pairs[[#This Row],[Az*]]=0, pairs[[#This Row],[Back*]]=0), OR(pairs[[#This Row],[Az*]]=1, pairs[[#This Row],[Back*]]=1)), 1, 0) -> 1 | J26: =IF(OR(pairs[[#This Row],[Az*]]=0.5,pairs[[#This Row],[Back*]]=0.5),1,0) -> 0
A27: Wb | B27: Ec | D27: 270.3 | E27: 7.076885 | F27: =pairs[[#This Row],[ Dist]]*5280 -> 37365.953 | G27: =ROUND(pairs[[#This Row],[ Az]]-ROUNDDOWN(pairs[[#This Row],[ Az]],0),1) -> 0 | H27: =ROUND(pairs[[#This Row],[ Back]]-ROUNDDOWN(pairs[[#This Row],[ Back]],0),1) -> 0.3 | I27: =IF( OR( OR(pairs[[#This Row],[Az*]]=0, pairs[[#This Row],[Back*]]=0), OR(pairs[[#This Row],[Az*]]=1, pairs[[#This Row],[Back*]]=1)), 1, 0) -> 1 | J27: =IF(OR(pairs[[#This Row],[Az*]]=0.5,pairs[[#This Row],[Back*]]=0.5),1,0) -> 0
A28: Wb | B28: HawC | D28: 271.94 | E28: 8.824801 | F28: =pairs[[#This Row],[ Dist]]*5280 -> 46594.949 | G28: =ROUND(pairs[[#This Row],[ Az]]-ROUNDDOWN(pairs[[#This Row],[ Az]],0),1) -> 0 | H28: =ROUND(pairs[[#This Row],[ Back]]-ROUNDDOWN(pairs[[#This Row],[ Back]],0),1) -> 0.9 | I28: =IF( OR( OR(pairs[[#This Row],[Az*]]=0, pairs[[#This Row],[Back*]]=0), OR(pairs[[#This Row],[Az*]]=1, pairs[[#This Row],[Back*]]=1)), 1, 0) -> 1 | J28: =IF(OR(pairs[[#This Row],[Az*]]=0.5,pairs[[#This Row],[Back*]]=0.5),1,0) -> 0
A29: Wb | B29: HawK | D29: 270.52 | E29: 6.532608 | F29: =pairs[[#This Row],[ Dist]]*5280 -> 34492.17 | G29: =ROUND(pairs[[#This Row],[ Az]]-ROUNDDOWN(pairs[[#This Row],[ Az]],0),1) -> 0 | H29: =ROUND(pairs[[#This Row],[ Back]]-ROUNDDOWN(pairs[[#This Row],[ Back]],0),1) -> 0.5 | I29: =IF( OR( OR(pairs[[#This Row],[Az*]]=0, pairs[[#This Row],[Back*]]=0), OR(pairs[[#This Row],[Az*]]=1, pairs[[#This Row],[Back*]]=1)), 1, 0) -> 1 | J29: =IF(OR(pairs[[#This Row],[Az*]]=0.5,pairs[[#This Row],[Back*]]=0.5),1,0) -> 1
A30: Wb | B30: HawW | D30: 267.91 | E30: 7.392033 | F30: =pairs[[#This Row],[ Dist]]*5280 -> 39029.934 | G30: =ROUND(pairs[[#This Row],[ Az]]-ROUNDDOWN(pairs[[#This Row],[ Az]],0),1) -> 0 | H30: =ROUND(pairs[[#This Row],[ Back]]-ROUNDDOWN(pairs[[#This Row],[ Back]],0),1) -> 0.9 | I30: =IF( OR( OR(pairs[[#This Row],[Az*]]=0, pairs[[#This Row],[Back*]]=0), OR(pairs[[#This Row],[Az*]]=1, pairs[[#This Row],[Back*]]=1)), 1, 0) -> 1 | J30: =IF(OR(pairs[[#This Row],[Az*]]=0.5,pairs[[#This Row],[Back*]]=0.5),1,0) -> 0
A31: Wb | B31: Hk | D31: 268.89 | E31: 6.499262 | F31: =pairs[[#This Row],[ Dist]]*5280 -> 34316.103 | G31: =ROUND(pairs[[#This Row],[ Az]]-ROUNDDOWN(pairs[[#This Row],[ Az]],0),1) -> 0 | H31: =ROUND(pairs[[#This Row],[ Back]]-ROUNDDOWN(pairs[[#This Row],[ Back]],0),1) -> 0.9 | I31: =IF( OR( OR(pairs[[#This Row],[Az*]]=0, pairs[[#This Row],[Back*]]=0), OR(pairs[[#This Row],[Az*]]=1, pairs[[#This Row],[Back*]]=1)), 1, 0) -> 1 | J31: =IF(OR(pairs[[#This Row],[Az*]]=0.5,pairs[[#This Row],[Back*]]=0.5),1,0) -> 0
A32: Wb | B32: J | D32: 271.91 | E32: 7.301856 | F32: =pairs[[#This Row],[ Dist]]*5280 -> 38553.8 | G32: =ROUND(pairs[[#This Row],[ Az]]-ROUNDDOWN(pairs[[#This Row],[ Az]],0),1) -> 0 | H32: =ROUND(pairs[[#This Row],[ Back]]-ROUNDDOWN(pairs[[#This Row],[ Back]],0),1) -> 0.9 | I32: =IF( OR( OR(pairs[[#This Row],[Az*]]=0, pairs[[#This Row],[Back*]]=0), OR(pairs[[#This Row],[Az*]]=1, pairs[[#This Row],[Back*]]=1)), 1, 0) -> 1 | J32: =IF(OR(pairs[[#This Row],[Az*]]=0.5,pairs[[#This Row],[Back*]]=0.5),1,0) -> 0
A33: Wb | B33: K | D33: 270.34 | E33: 6.498147 | F33: =pairs[[#This Row],[ Dist]]*5280 -> 34310.216 | G33: =ROUND(pairs[[#This Row],[ Az]]-ROUNDDOWN(pairs[[#This Row],[ Az]],0),1) -> 0 | H33: =ROUND(pairs[[#This Row],[ Back]]-ROUNDDOWN(pairs[[#This Row],[ Back]],0),1) -> 0.3 | I33: =IF( OR( OR(pairs[[#This Row],[Az*]]=0, pairs[[#This Row],[Back*]]=0), OR(pairs[[#This Row],[Az*]]=1, pairs[[#This Row],[Back*]]=1)), 1, 0) -> 1 | J33: =IF(OR(pairs[[#This Row],[Az*]]=0.5,pairs[[#This Row],[Back*]]=0.5),1,0) -> 0
A34: Wb | B34: M | D34: 272.08 | E34: 7.373497 | F34: =pairs[[#This Row],[ Dist]]*5280 -> 38932.064 | G34: =ROUND(pairs[[#This Row],[ Az]]-ROUNDDOWN(pairs[[#This Row],[ Az]],0),1) -> 0 | H34: =ROUND(pairs[[#This Row],[ Back]]-ROUNDDOWN(pairs[[#This Row],[ Back]],0),1) -> 0.1 | I34: =IF( OR( OR(pairs[[#This Row],[Az*]]=0, pairs[[#This Row],[Back*]]=0), OR(pairs[[#This Row],[Az*]]=1, pairs[[#This Row],[Back*]]=1)), 1, 0) -> 1 | J34: =IF(OR(pairs[[#This Row],[Az*]]=0.5,pairs[[#This Row],[Back*]]=0.5),1,0) -> 0
A35: Wb | B35: Nb | D35: 224.88 | E35: 10.00599 | F35: =pairs[[#This Row],[ Dist]]*5280 -> 52831.627 | G35: =ROUND(pairs[[#This Row],[ Az]]-ROUNDDOWN(pairs[[#This Row],[ Az]],0),1) -> 0 | H35: =ROUND(pairs[[#This Row],[ Back]]-ROUNDDOWN(pairs[[#This Row],[ Back]],0),1) -> 0.9 | I35: =IF( OR( OR(pairs[[#This Row],[Az*]]=0, pairs[[#This Row],[Back*]]=0), OR(pairs[[#This Row],[Az*]]=1, pairs[[#This Row],[Back*]]=1)), 1, 0) -> 1 | J35: =IF(OR(pairs[[#This Row],[Az*]]=0.5,pairs[[#This Row],[Back*]]=0.5),1,0) -> 0
... A39: Wb | B39: RC | D39: 224.96 | E39: 9.174392 | F39: =pairs[[#This Row],[ Dist]]*5280 -> 48440.79 | G39: =ROUND(pairs[[#This Row],[ Az]]-ROUNDDOWN(pairs[[#This Row],[ Az]],0),1) -> 0 | H39: =ROUND(pairs[[#This Row],[ Back]]-ROUNDDOWN(pairs[[#This Row],[ Back]],0),1) -> 1 | I39: =IF( OR( OR(pairs[[#This Row],[Az*]]=0, pairs[[#This Row],[Back*]]=0), OR(pairs[[#This Row],[Az*]]=1, pairs[[#This Row],[Back*]]=1)), 1, 0) -> 1 | J39: =IF(OR(pairs[[#This Row],[Az*]]=0.5,pairs[[#This Row],[Back*]]=0.5),1,0) -> 0
A40: Wb | B40: RK | D40: 288.26 | E40: 8.421389 | F40: =pairs[[#This Row],[ Dist]]*5280 -> 44464.934 | G40: =ROUND(pairs[[#This Row],[ Az]]-ROUNDDOWN(pairs[[#This Row],[ Az]],0),1) -> 0 | H40: =ROUND(pairs[[#This Row],[ Back]]-ROUNDDOWN(pairs[[#This Row],[ Back]],0),1) -> 0.3 | I40: =IF( OR( OR(pairs[[#This Row],[Az*]]=0, pairs[[#This Row],[Back*]]=0), OR(pairs[[#This Row],[Az*]]=1, pairs[[#This Row],[Back*]]=1)), 1, 0) -> 1 | J40: 1
A41: Wb | B41: Sb | D41: 315.13 | E41: 10.037895 | F41: =pairs[[#This Row],[ Dist]]*5280 -> 53000.086 | G41: =ROUND(pairs[[#This Row],[ Az]]-ROUNDDOWN(pairs[[#This Row],[ Az]],0),1) -> 0 | H41: =ROUND(pairs[[#This Row],[ Back]]-ROUNDDOWN(pairs[[#This Row],[ Back]],0),1) -> 0.1 | I41: =IF( OR( OR(pairs[[#This Row],[Az*]]=0, pairs[[#This Row],[Back*]]=0), OR(pairs[[#This Row],[Az*]]=1, pairs[[#This Row],[Back*]]=1)), 1, 0) -> 1 | J41: =IF(OR(pairs[[#This Row],[Az*]]=0.5,pairs[[#This Row],[Back*]]=0.5),1,0) -> 0
A42: Wb | B42: Sc | D42: 270.35 | E42: 7.081955 | F42: =pairs[[#This Row],[ Dist]]*5280 -> 37392.722 | G42: =ROUND(pairs[[#This Row],[ Az]]-ROUNDDOWN(pairs[[#This Row],[ Az]],0),1) -> 0 | H42: =ROUND(pairs[[#This Row],[ Back]]-ROUNDDOWN(pairs[[#This Row],[ Back]],0),1) -> 0.4 | I42: =IF( OR( OR(pairs[[#This Row],[Az*]]=0, pairs[[#This Row],[Back*]]=0), OR(pairs[[#This Row],[Az*]]=1, pairs[[#This Row],[Back*]]=1)), 1, 0) -> 1 | J42: =IF(OR(pairs[[#This Row],[Az*]]=0.5,pairs[[#This Row],[Back*]]=0.5),1,0) -> 0
A43: Wb | B43: Wc | D43: 270.08 | E43: 7.071068 | F43: =pairs[[#This Row],[ Dist]]*5280 -> 37335.239 | G43: =ROUND(pairs[[#This Row],[ Az]]-ROUNDDOWN(pairs[[#This Row],[ Az]],0),1) -> 0 | H43: =ROUND(pairs[[#This Row],[ Back]]-ROUNDDOWN(pairs[[#This Row],[ Back]],0),1) -> 0.1 | I43: =IF( OR( OR(pairs[[#This Row],[Az*]]=0, pairs[[#This Row],[Back*]]=0), OR(pairs[[#This Row],[Az*]]=1, pairs[[#This Row],[Back*]]=1)), 1, 0) -> 1 | J43: =IF(OR(pairs[[#This Row],[Az*]]=0.5,pairs[[#This Row],[Back*]]=0.5),1,0) -> 0
A44: Sc | B44: Ac | D44: 161.37 | E44: 0.029205 | F44: =pairs[[#This Row],[ Dist]]*5280 -> 154.2024 | G44: =ROUND(pairs[[#This Row],[ Az]]-ROUNDDOWN(pairs[[#This Row],[ Az]],0),1) -> 0 | H44: =ROUND(pairs[[#This Row],[ Back]]-ROUNDDOWN(pairs[[#This Row],[ Back]],0),1) -> 0.4 | I44: =IF( OR( OR(pairs[[#This Row],[Az*]]=0, pairs[[#This Row],[Back*]]=0), OR(pairs[[#This Row],[Az*]]=1, pairs[[#This Row],[Back*]]=1)), 1, 0) -> 1 | J44: =IF(OR(pairs[[#This Row],[Az*]]=0.5,pairs[[#This Row],[Back*]]=0.5),1,0) -> 0
A45: Sc | B45: AN | D45: 251.4 | E45: 5.597158 | F45: =pairs[[#This Row],[ Dist]]*5280 -> 29552.994 | G45: =ROUND(pairs[[#This Row],[ Az]]-ROUNDDOWN(pairs[[#This Row],[ Az]],0),1) -> 0 | H45: =ROUND(pairs[[#This Row],[ Back]]-ROUNDDOWN(pairs[[#This Row],[ Back]],0),1) -> 0.4 | I45: =IF( OR( OR(pairs[[#This Row],[Az*]]=0, pairs[[#This Row],[Back*]]=0), OR(pairs[[#This Row],[Az*]]=1, pairs[[#This Row],[Back*]]=1)), 1, 0) -> 1 | J45: =IF(OR(pairs[[#This Row],[Az*]]=0.5,pairs[[#This Row],[Back*]]=0.5),1,0) -> 0
A46: Sc | B46: B | D46: 269.89 | E46: 1.704462 | F46: =pairs[[#This Row],[ Dist]]*5280 -> 8999.5594 | G46: =ROUND(pairs[[#This Row],[ Az]]-ROUNDDOWN(pairs[[#This Row],[ Az]],0),1) -> 0 | H46: =ROUND(pairs[[#This Row],[ Back]]-ROUNDDOWN(pairs[[#This Row],[ Back]],0),1) -> 0.9 | I46: =IF( OR( OR(pairs[[#This Row],[Az*]]=0, pairs[[#This Row],[Back*]]=0), OR(pairs[[#This Row],[Az*]]=1, pairs[[#This Row],[Back*]]=1)), 1, 0) -> 1 | J46: =IF(OR(pairs[[#This Row],[Az*]]=0.5,pairs[[#This Row],[Back*]]=0.5),1,0) -> 0
A47: Sc | B47: Eb | D47: 269.95 | E47: 7.066042 | F47: =pairs[[#This Row],[ Dist]]*5280 -> 37308.702 | G47: =ROUND(pairs[[#This Row],[ Az]]-ROUNDDOWN(pairs[[#This Row],[ Az]],0),1) -> 0 | H47: =ROUND(pairs[[#This Row],[ Back]]-ROUNDDOWN(pairs[[#This Row],[ Back]],0),1) -> 0.9 | I47: 1 | J47: =IF(OR(pairs[[#This Row],[Az*]]=0.5,pairs[[#This Row],[Back*]]=0.5),1,0) -> 0
A48: Sc | B48: Ec | D48: 140.1 | E48: 0.007851 | F48: =pairs[[#This Row],[ Dist]]*5280 -> 41.45328 | G48: =ROUND(pairs[[#This Row],[ Az]]-ROUNDDOWN(pairs[[#This Row],[ Az]],0),1) -> 0 | H48: =ROUND(pairs[[#This Row],[ Back]]-ROUNDDOWN(pairs[[#This Row],[ Back]],0),1) -> 0.1 | I48: =IF( OR( OR(pairs[[#This Row],[Az*]]=0, pairs[[#This Row],[Back*]]=0), OR(pairs[[#This Row],[Az*]]=1, pairs[[#This Row],[Back*]]=1)), 1, 0) -> 1 | J48: =IF(OR(pairs[[#This Row],[Az*]]=0.5,pairs[[#This Row],[Back*]]=0.5),1,0) -> 0
A49: Sc | B49: HawC | D49: 278.29 | E49: 1.756278 | F49: =pairs[[#This Row],[ Dist]]*5280 -> 9273.1478 | G49: =ROUND(pairs[[#This Row],[ Az]]-ROUNDDOWN(pairs[[#This Row],[ Az]],0),1) -> 0 | H49: =ROUND(pairs[[#This Row],[ Back]]-ROUNDDOWN(pairs[[#This Row],[ Back]],0),1) -> 0.3 | I49: =IF( OR( OR(pairs[[#This Row],[Az*]]=0, pairs[[#This Row],[Back*]]=0), OR(pairs[[#This Row],[Az*]]=1, pairs[[#This Row],[Back*]]=1)), 1, 0) -> 1 | J49: =IF(OR(pairs[[#This Row],[Az*]]=0.5,pairs[[#This Row],[Back*]]=0.5),1,0) -> 0
A50: Sc | B50: HawK | D50: 88.17 | E50: 0.549775 | F50: =pairs[[#This Row],[ Dist]]*5280 -> 2902.812 | G50: =ROUND(pairs[[#This Row],[ Az]]-ROUNDDOWN(pairs[[#This Row],[ Az]],0),1) -> 0 | H50: =ROUND(pairs[[#This Row],[ Back]]-ROUNDDOWN(pairs[[#This Row],[ Back]],0),1) -> 0.2 | I50: =IF( OR( OR(pairs[[#This Row],[Az*]]=0, pairs[[#This Row],[Back*]]=0), OR(pairs[[#This Row],[Az*]]=1, pairs[[#This Row],[Back*]]=1)), 1, 0) -> 1 | J50: =IF(OR(pairs[[#This Row],[Az*]]=0.5,pairs[[#This Row],[Back*]]=0.5),1,0) -> 0
A51: Sc | B51: HawW | D51: 224.28 | E51: 0.437279 | F51: =pairs[[#This Row],[ Dist]]*5280 -> 2308.8331 | G51: =ROUND(pairs[[#This Row],[ Az]]-ROUNDDOWN(pairs[[#This Row],[ Az]],0),1) -> 0 | H51: =ROUND(pairs[[#This Row],[ Back]]-ROUNDDOWN(pairs[[#This Row],[ Back]],0),1) -> 0.3 | I51: =IF( OR( OR(pairs[[#This Row],[Az*]]=0, pairs[[#This Row],[Back*]]=0), OR(pairs[[#This Row],[Az*]]=1, pairs[[#This Row],[Back*]]=1)), 1, 0) -> 1 | J51: =IF(OR(pairs[[#This Row],[Az*]]=0.5,pairs[[#This Row],[Back*]]=0.5),1,0) -> 0
...

Sheet linepairs
A1: REF | B1: TARG
A2: AN | B2: Sb | C2: =A2 & "," & B2 -> AN, Sb
A3: AN | B3: RK | C3: =A3 & "," & B3 -> AN, RK
A4: AN | B4: Nc | C4: =A4 & "," & B4 -> AN, Nc
A5: AN | B5: Wb | C5: =A5 & "," & B5 -> AN, Wb
A6: B | B6: K | C6: =A6 & "," & B6 -> B, K
A7: B | B7: Wc | C7: =A7 & "," & B7 -> B, Wc
A8: CapA | B8: CapJ | C8: =A8 & "," & B8 -> CapA, CapJ
A9: CapA | B9: CapL | C9: =A9 & "," & B9 -> CapA, CapL
A10: CapA | B10: CapF | C10: =A10 & "," & B10 -> CapA, CapF
A11: CapC | B11: CapK | C11: =A11 & "," & B11 -> CapC, CapK
A12: CapE | B12: CapL | C12: =A12 & "," & B12 -> CapE, CapL
A13: CapF | B13: CapA | C13: =A13 & "," & B13 -> CapF, CapA
... A239: Wb | B239: RK | C239: =A239 & "," & B239 -> Wb, RK

Sheet geo inv
B1: K | C1: B | D1: W | E1: Cap | F1: M | G1: J | H1: Hk
A2: K | C2: 2.2882538 | D2: 0.874037 | E2: 2.279538 | F2: 0.900118 | G2: 0.8253388 | H2: 0.1648
A3: B | B3: 89.98664 | E3: 0.2045 | G3: 1.50239 | H3: 2.29414
A4: W | B4: 66.2011 | E4: 1.5723 | G4: 0.556399 | H4: 0.82149
A5: Cap | B5: 95.1152 | C5: 5.017 | D5: 110.71 | F5: 1.400058 | G5: 1.47065 | H5: 2.300096
A6: M | B6: 104.70637 | E6: 88.976 | G6: 0.0750427 | H6: 0.9553
A7: J | B7: 104.28872 | C7: 82.1964 | D7: 0 | E7: 89.9914 | F7: 109.314 | H7: 0.880614
A8: Hk | B8: 0 | C8: 94.106 | D8: 76.7776 | E8: 99.2074 | F8: 114.311 | G8: 294.746

Sheet nums
D2: ="x phi+" -> x phi+ | E2: ="x phi+" -> x phi+ | F2: ="x phi-" -> x phi- | G2: ="x phi-" -> x phi- | H2: ="/2" -> /2 | I2: ="/2" -> /2 | J2: ="/rad2" -> /rad2 | K2: ="1/rad2" -> 1/rad2
B3: ft | C3: mi | D3: ft | E3: mi | F3: ft | G3: mi | H3: ft | I3: mi | J3: ft | K3: mi
A4: ="1/rad2" -> 1/rad2 | B4: =5280*C4 -> 3733.5238 | C4: =1/SQRT(2) -> 0.70710678 | D4: =5280*E4 -> 6040.9684 | E4: =C4*(1+SQRT(5))/2 -> 1.1441228 | F4: =5280*G4 -> 2307.4446 | G4: =2 * C4 / (1+SQRT(5)) -> 0.43701602 | H4: =5280*I4 -> 1866.7619 | I4: =C4/2 -> 0.35355339 | J4: =5280*K4 -> 2640 | K4: =C4/SQRT(2) -> 0.5
A5: ="1/2" -> 1/2 | B5: =5280*C5 -> 2640 | C5: =1/2 -> 0.5 | D5: =5280*E5 -> 4271.6097 | E5: =C5*(1+SQRT(5))/2 -> 0.80901699 | F5: =5280*G5 -> 1631.6097 | G5: =2 * C5 / (1+SQRT(5)) -> 0.30901699 | H5: =5280*I5 -> 1320 | I5: =C5/2 -> 0.25 | J5: =5280*K5 -> 1866.7619 | K5: =C5/SQRT(2) -> 0.35355339
A6: ="1" -> 1 | B6: =5280*C6 -> 5280 | C6: 1 | D6: =5280*E6 -> 8543.2195 | E6: =C6*(1+SQRT(5))/2 -> 1.618034 | F6: =5280*G6 -> 3263.2195 | G6: =2 * C6 / (1+SQRT(5)) -> 0.61803399 | H6: =5280*I6 -> 2640 | I6: =C6/2 -> 0.5 | J6: =5280*K6 -> 3733.5238 | K6: =C6/SQRT(2) -> 0.70710678
A7: ="rad2" -> rad2 | B7: =5280*C7 -> 7467.0476 | C7: =SQRT(2) -> 1.4142136 | D7: =5280*E7 -> 12081.937 | E7: =C7*(1+SQRT(5))/2 -> 2.2882456 | F7: =5280*G7 -> 4614.8892 | G7: =2 * C7 / (1+SQRT(5)) -> 0.87403205 | H7: =5280*I7 -> 3733.5238 | I7: =C7/2 -> 0.70710678 | J7: =5280*K7 -> 5280 | K7: =C7/SQRT(2) -> 1
A8: ="rad3" -> rad3 | B8: =5280*C8 -> 9145.2283 | C8: =SQRT(3) -> 1.7320508 | D8: =5280*E8 -> 14797.29 | E8: =C8*(1+SQRT(5))/2 -> 2.8025171 | F8: =5280*G8 -> 5652.0619 | G8: =2 * C8 / (1+SQRT(5)) -> 1.0704663 | H8: =5280*I8 -> 4572.6141 | I8: =C8/2 -> 0.8660254 | J8: =5280*K8 -> 6466.6529 | K8: =C8/SQRT(2) -> 1.2247449
A9: ="rad5" -> rad5 | B9: =5280*C9 -> 11806.439 | C9: =SQRT(5) -> 2.236068 | D9: =5280*E9 -> 19103.219 | E9: =C9*(1+SQRT(5))/2 -> 3.618034 | F9: =5280*G9 -> 7296.7805 | G9: =2 * C9 / (1+SQRT(5)) -> 1.381966 | H9: =5280*I9 -> 5903.2195 | I9: =C9/2 -> 1.118034 | J9: =5280*K9 -> 8348.413 | K9: =C9/SQRT(2) -> 1.5811388
A10: ="phi+" -> phi+ | B10: =5280*C10 -> 8543.2195 | C10: =(1+SQRT(5))/2 -> 1.618034 | D10: =5280*E10 -> 13823.219 | E10: =C10*(1+SQRT(5))/2 -> 2.618034 | F10: =5280*G10 -> 5280 | G10: =2 * C10 / (1+SQRT(5)) -> 1 | H10: =5280*I10 -> 4271.6097 | I10: =C10/2 -> 0.80901699 | J10: =5280*K10 -> 6040.9684 | K10: =C10/SQRT(2) -> 1.1441228
A11: ="phi+^2" -> phi+^2 | B11: =5280*C11 -> 13823.219 | C11: =C10^2 -> 2.618034 | D11: =5280*E11 -> 22366.439 | E11: =C11*(1+SQRT(5))/2 -> 4.236068 | F11: =5280*G11 -> 8543.2195 | G11: =2 * C11 / (1+SQRT(5)) -> 1.618034 | H11: =5280*I11 -> 6911.6097 | I11: =C11/2 -> 1.309017 | J11: =5280*K11 -> 9774.4922 | K11: =C11/SQRT(2) -> 1.8512296
A12: ="phi-" -> phi- | B12: =5280*C12 -> 3263.2195 | C12: =1/C10 -> 0.61803399 | D12: =5280*E12 -> 5280 | E12: =C12*(1+SQRT(5))/2 -> 1 | F12: =5280*G12 -> 2016.7805 | G12: =2 * C12 / (1+SQRT(5)) -> 0.38196601 | H12: =5280*I12 -> 1631.6097 | I12: =C12/2 -> 0.30901699 | J12: =5280*K12 -> 2307.4446 | K12: =C12/SQRT(2) -> 0.43701602
A13: ="phi-^2" -> phi-^2 | B13: =5280*C13 -> 2016.7805 | C13: =C12^2 -> 0.38196601 | D13: =5280*E13 -> 3263.2195 | E13: =C13*(1+SQRT(5))/2 -> 0.61803399 | F13: =5280*G13 -> 1246.4389 | G13: =2 * C13 / (1+SQRT(5)) -> 0.23606798 | H13: =5280*I13 -> 1008.3903 | I13: =C13/2 -> 0.19098301 | J13: =5280*K13 -> 1426.0792 | K13: =C13/SQRT(2) -> 0.27009076
A14: radphi | B14: =5280*C14 -> 6716.2637 | C14: =SQRT(C10) -> 1.2720196 | D14: =5280*E14 -> 10867.143 | E14: =C14*(1+SQRT(5))/2 -> 2.058171 | F14: =5280*G14 -> 4150.8793 | G14: =2 * C14 / (1+SQRT(5)) -> 0.78615138 | H14: =5280*I14 -> 3358.1319 | I14: =C14/2 -> 0.63600982 | J14: =5280*K14 -> 4749.1156 | K14: =C14/SQRT(2) -> 0.89945372
A15: rad2radphi | B15: =5280*C15 -> 9498.2313 | C15: =C14*C7 -> 1.7989074 | D15: =5280*E15 -> 15368.461 | E15: =C15*(1+SQRT(5))/2 -> 2.9106934 | F15: =5280*G15 -> 5870.2298 | G15: =2 * C15 / (1+SQRT(5)) -> 1.1117859 | H15: =5280*I15 -> 4749.1156 | I15: =C15/2 -> 0.89945372 | J15: =5280*K15 -> 6716.2637 | K15: =C15/SQRT(2) -> 1.2720196
I18: Feet | J18: Fraction | K18: one | L18: phi+ | M18: phi- | N18: phi+/2 | O18: phi-/2 | P18: rad2 | Q18: rad3 | R18: rad5 | S18: rad3/2 | T18: ="/2" -> /2
A19: Miles: | B19: 1 | C19: phi+ | D19: phi- | E19: ="/2" -> /2 | F19: phi+/2 | G19: phi-/2 | J19: 0.5 | K19: =J19*5280 -> 2640 | L19: =K19*(1+SQRT(5))/2 -> 4271.6097 | M19: =K19*(SQRT(5)-1)/2 -> 1631.6097 | N19: =L19/2 -> 2135.8049 | O19: =M19/2 -> 815.80487 | P19: =K19*SQRT(2) -> 3733.5238 | Q19: =K19*SQRT(3) -> 4572.6141 | R19: =K19*SQRT(5) -> 5903.2195 | S19: =Q19/2 -> 2286.3071 | T19: =K19*0.5 -> 1320
B20: 1 | C20: =(1+SQRT(5))/2 -> 1.618034 | D20: =(SQRT(5)-1)/2 -> 0.61803399 | E20: 0.5 | F20: =C20/2 -> 0.80901699 | G20: =D20/2 -> 0.30901699 | J20: =1/3 -> 0.33333333 | K20: =J20*5280 -> 1760 | L20: =K20*(1+SQRT(5))/2 -> 2847.7398 | M20: =K20*(SQRT(5)-1)/2 -> 1087.7398 | N20: =L20/2 -> 1423.8699 | O20: =M20/2 -> 543.86991 | P20: =K20*SQRT(2) -> 2489.0159 | Q20: =K20*SQRT(3) -> 3048.4094 | R20: =K20*SQRT(5) -> 3935.4796 | S20: =Q20/2 -> 1524.2047 | T20: =K20*0.5 -> 880
A21: rad2 | B21: =SQRT(2) -> 1.4142136 | C21: =B21*C20 -> 2.2882456 | D21: =B21*D20 -> 0.87403205 | E21: =B21*E20 -> 0.70710678 | F21: =E21*C20 -> 1.1441228 | G21: =E21*D20 -> 0.43701602 | J21: =1/4 -> 0.25 | K21: =J21*5280 -> 1320 | L21: =K21*(1+SQRT(5))/2 -> 2135.8049 | M21: =K21*(SQRT(5)-1)/2 -> 815.80487 | N21: =L21/2 -> 1067.9024 | O21: =M21/2 -> 407.90243 | P21: =K21*SQRT(2) -> 1866.7619 | Q21: =K21*SQRT(3) -> 2286.3071 | R21: =K21*SQRT(5) -> 2951.6097 | S21: =Q21/2 -> 1143.1535 | T21: =K21*0.5 -> 660
A22: rad3 | B22: =SQRT(3) -> 1.7320508 | C22: =B22*C20 -> 2.8025171 | D22: =B22*D20 -> 1.0704663 | E22: =E20*B22 -> 0.8660254 | F22: =E22*C20 -> 1.4012585 | G22: =E22*D20 -> 0.53523313 | J22: =1/5 -> 0.2 | K22: =J22*5280 -> 1056 | L22: =K22*(1+SQRT(5))/2 -> 1708.6439 | M22: =K22*(SQRT(5)-1)/2 -> 652.64389 | N22: =L22/2 -> 854.32195 | O22: =M22/2 -> 326.32195 | P22: =K22*SQRT(2) -> 1493.4095 | Q22: =K22*SQRT(3) -> 1829.0457 | R22: =K22*SQRT(5) -> 2361.2878 | S22: =Q22/2 -> 914.52283 | T22: =K22*0.5 -> 528
A23: rad5 | B23: =SQRT(5) -> 2.236068 | C23: =B23*C22 -> 6.2666187 | D23: =B23*D22 -> 2.3936353 | E23: =B23*E22 -> 1.9364917 | F23: =E23*C22 -> 5.427051 | G23: =E23*D22 -> 2.072949 | J23: =1/6 -> 0.16666667 | K23: =J23*5280 -> 880 | L23: =K23*(1+SQRT(5))/2 -> 1423.8699 | M23: =K23*(SQRT(5)-1)/2 -> 543.86991 | N23: =L23/2 -> 711.93496 | O23: =M23/2 -> 271.93496 | P23: =K23*SQRT(2) -> 1244.5079 | Q23: =K23*SQRT(3) -> 1524.2047 | R23: =K23*SQRT(5) -> 1967.7398 | S23: =Q23/2 -> 762.10236 | T23: =K23*0.5 -> 440
A24: Feet: | J24: =1/7 -> 0.14285714 | K24: =J24*5280 -> 754.28571 | L24: =K24*(1+SQRT(5))/2 -> 1220.4599 | M24: =K24*(SQRT(5)-1)/2 -> 466.17421 | N24: =L24/2 -> 610.22996 | O24: =M24/2 -> 233.0871 | P24: =K24*SQRT(2) -> 1066.7211 | Q24: =K24*SQRT(3) -> 1306.4612 | R24: =K24*SQRT(5) -> 1686.6341 | S24: =Q24/2 -> 653.23059 | T24: =K24*0.5 -> 377.14286
B25: =CONVERT(B20,"mi","ft") -> 5280 | C25: =CONVERT(C20,"mi","ft") -> 8543.2195 | D25: =CONVERT(D20,"mi","ft") -> 3263.2195 | E25: =CONVERT(E20,"mi","ft") -> 2640 | F25: =CONVERT(F20,"mi","ft") -> 4271.6097 | G25: =CONVERT(G20,"mi","ft") -> 1631.6097 | J25: =1/8 -> 0.125 | K25: =J25*5280 -> 660 | L25: =K25*(1+SQRT(5))/2 -> 1067.9024 | M25: =K25*(SQRT(5)-1)/2 -> 407.90243 | N25: =L25/2 -> 533.95122 | O25: =M25/2 -> 203.95122 | P25: =K25*SQRT(2) -> 933.38095 | Q25: =K25*SQRT(3) -> 1143.1535 | R25: =K25*SQRT(5) -> 1475.8049 | S25: =Q25/2 -> 571.57677 | T25: =K25*0.5 -> 330
B26: =CONVERT(B21,"mi","ft") -> 7467.0476 | C26: =CONVERT(C21,"mi","ft") -> 12081.937 | D26: =CONVERT(D21,"mi","ft") -> 4614.8892 | E26: =CONVERT(E21,"mi","ft") -> 3733.5238 | F26: =CONVERT(F21,"mi","ft") -> 6040.9684 | G26: =CONVERT(G21,"mi","ft") -> 2307.4446 | J26: =1/9 -> 0.11111111 | K26: =J26*5280 -> 586.66667 | L26: =K26*(1+SQRT(5))/2 -> 949.24661 | M26: =K26*(SQRT(5)-1)/2 -> 362.57994 | N26: =L26/2 -> 474.6233 | O26: =M26/2 -> 181.28997 | P26: =K26*SQRT(2) -> 829.67196 | Q26: =K26*SQRT(3) -> 1016.1365 | R26: =K26*SQRT(5) -> 1311.8265 | S26: =Q26/2 -> 508.06824 | T26: =K26*0.5 -> 293.33333
B27: =CONVERT(B22,"mi","ft") -> 9145.2283 | C27: =CONVERT(C22,"mi","ft") -> 14797.29 | D27: =CONVERT(D22,"mi","ft") -> 5652.0619 | E27: =CONVERT(E22,"mi","ft") -> 4572.6141 | F27: =CONVERT(F22,"mi","ft") -> 7398.6451 | G27: =CONVERT(G22,"mi","ft") -> 2826.031 | I27: Poles | J27: Fraction | K27: one | L27: phi+ | M27: phi- | N27: phi+/2 | O27: phi-/2 | P27: rad2 | Q27: rad3 | R27: rad5 | S27: rad3/2 | T27: ="/2" -> /2
B28: =CONVERT(B23,"mi","ft") -> 11806.439 | C28: =CONVERT(C23,"mi","ft") -> 33087.747 | D28: =CONVERT(D23,"mi","ft") -> 12638.395 | E28: =CONVERT(E23,"mi","ft") -> 10224.676 | F28: =CONVERT(F23,"mi","ft") -> 28654.829 | G28: =CONVERT(G23,"mi","ft") -> 10945.171 | J28: 0.5 | K28: =J28*320 -> 160 | L28: =K28*(1+SQRT(5))/2 -> 258.88544 | M28: =K28*(SQRT(5)-1)/2 -> 98.885438 | N28: =L28/2 -> 129.44272 | O28: =M28/2 -> 49.442719 | P28: =K28*SQRT(2) -> 226.27417 | Q28: =K28*SQRT(3) -> 277.12813 | R28: =K28*SQRT(5) -> 357.77088 | S28: =Q28/2 -> 138.56406 | T28: =K28*0.5 -> 80
A29: Poles: | J29: =1/3 -> 0.33333333 | K29: =J29*320 -> 106.66667 | L29: =K29*(1+SQRT(5))/2 -> 172.59029 | M29: =K29*(SQRT(5)-1)/2 -> 65.923625 | N29: =L29/2 -> 86.295146 | O29: =M29/2 -> 32.961813 | P29: =K29*SQRT(2) -> 150.84945 | Q29: =K29*SQRT(3) -> 184.75209 | R29: =K29*SQRT(5) -> 238.51392 | S29: =Q29/2 -> 92.376043 | T29: =K29*0.5 -> 53.333333
B30: =B20*320 -> 320 | C30: =C20*320 -> 517.77088 | D30: =D20*320 -> 197.77088 | E30: =E20*320 -> 160 | F30: =F20*320 -> 258.88544 | G30: =G20*320 -> 98.885438 | J30: =1/4 -> 0.25 | K30: =J30*320 -> 80 | L30: =K30*(1+SQRT(5))/2 -> 129.44272 | M30: =K30*(SQRT(5)-1)/2 -> 49.442719 | N30: =L30/2 -> 64.72136 | O30: =M30/2 -> 24.72136 | P30: =K30*SQRT(2) -> 113.13708 | Q30: =K30*SQRT(3) -> 138.56406 | R30: =K30*SQRT(5) -> 178.88544 | S30: =Q30/2 -> 69.282032 | T30: =K30*0.5 -> 40
B31: =B22*320 -> 554.25626 | C31: =C22*320 -> 896.80546 | D31: =D22*320 -> 342.54921 | E31: =E22*320 -> 277.12813 | F31: =F22*320 -> 448.40273 | G31: =G22*320 -> 171.2746 | J31: =1/5 -> 0.2 | K31: =J31*320 -> 64 | L31: =K31*(1+SQRT(5))/2 -> 103.55418 | M31: =K31*(SQRT(5)-1)/2 -> 39.554175 | N31: =L31/2 -> 51.777088 | O31: =M31/2 -> 19.777088 | P31: =K31*SQRT(2) -> 90.509668 | Q31: =K31*SQRT(3) -> 110.85125 | R31: =K31*SQRT(5) -> 143.10835 | S31: =Q31/2 -> 55.425626 | T31: =K31*0.5 -> 32
B32: =B21*320 -> 452.54834 | C32: =C21*320 -> 732.2386 | D32: =D21*320 -> 279.69026 | E32: =E21*320 -> 226.27417 | F32: =F21*320 -> 366.1193 | G32: =G21*320 -> 139.84513 | J32: =1/6 -> 0.16666667 | K32: =J32*320 -> 53.333333 | L32: =K32*(1+SQRT(5))/2 -> 86.295146 | M32: =K32*(SQRT(5)-1)/2 -> 32.961813 | N32: =L32/2 -> 43.147573 | O32: =M32/2 -> 16.480906 | P32: =K32*SQRT(2) -> 75.424723 | Q32: =K32*SQRT(3) -> 92.376043 | R32: =K32*SQRT(5) -> 119.25696 | S32: =Q32/2 -> 46.188022 | T32: =K32*0.5 -> 26.666667
B33: =B23*320 -> 715.54175 | C33: =C23*320 -> 2005.318 | D33: =D23*320 -> 765.96331 | E33: =E23*320 -> 619.67734 | F33: =F23*320 -> 1736.6563 | G33: =G23*320 -> 663.34369 | J33: =1/7 -> 0.14285714 | K33: =J33*320 -> 45.714286 | L33: =K33*(1+SQRT(5))/2 -> 73.967268 | M33: =K33*(SQRT(5)-1)/2 -> 28.252982 | N33: =L33/2 -> 36.983634 | O33: =M33/2 -> 14.126491 | P33: =K33*SQRT(2) -> 64.649763 | Q33: =K33*SQRT(3) -> 79.179465 | R33: =K33*SQRT(5) -> 102.22025 | S33: =Q33/2 -> 39.589733 | T33: =K33*0.5 -> 22.857143
A34: Chains: | J34: =1/8 -> 0.125 | K34: =J34*320 -> 40 | L34: =K34*(1+SQRT(5))/2 -> 64.72136 | M34: =K34*(SQRT(5)-1)/2 -> 24.72136 | N34: =L34/2 -> 32.36068 | O34: =M34/2 -> 12.36068 | P34: =K34*SQRT(2) -> 56.568542 | Q34: =K34*SQRT(3) -> 69.282032 | R34: =K34*SQRT(5) -> 89.442719 | S34: =Q34/2 -> 34.641016 | T34: =K34*0.5 -> 20
B35: =B20*80 -> 80 | C35: =C20*80 -> 129.44272 | D35: =D20*80 -> 49.442719 | E35: =E20*80 -> 40 | F35: =F20*80 -> 64.72136 | G35: =G20*80 -> 24.72136 | J35: =1/9 -> 0.11111111 | K35: =J35*320 -> 35.555556 | L35: =K35*(1+SQRT(5))/2 -> 57.530097 | M35: =K35*(SQRT(5)-1)/2 -> 21.974542 | N35: =L35/2 -> 28.765049 | O35: =M35/2 -> 10.987271 | P35: =K35*SQRT(2) -> 50.283149 | Q35: =K35*SQRT(3) -> 61.584029 | R35: =K35*SQRT(5) -> 79.504639 | S35: =Q35/2 -> 30.792014 | T35: =K35*0.5 -> 17.777778
B36: =B22*80 -> 138.56406 | C36: =C22*80 -> 224.20137 | D36: =D22*80 -> 85.637302 | E36: =E22*80 -> 69.282032 | F36: =F22*80 -> 112.10068 | G36: =G22*80 -> 42.818651 | I36: Chains | J36: Fraction | K36: one | L36: phi+ | M36: phi- | N36: phi+/2 | O36: phi-/2 | P36: rad2 | Q36: rad3 | R36: rad5 | S36: rad3/2 | T36: ="/2" -> /2
B37: =B21*80 -> 113.13708 | C37: =C21*80 -> 183.05965 | D37: =D21*80 -> 69.922564 | E37: =E21*80 -> 56.568542 | F37: =F21*80 -> 91.529824 | G37: =G21*80 -> 34.961282 | I37: ="1/2" -> 1/2 | J37: 0.5 | K37: =J37*80 -> 40 | L37: =K37*(1+SQRT(5))/2 -> 64.72136 | M37: =K37*(SQRT(5)-1)/2 -> 24.72136 | N37: =L37/2 -> 32.36068 | O37: =M37/2 -> 12.36068 | P37: =K37*SQRT(2) -> 56.568542 | Q37: =K37*SQRT(3) -> 69.282032 | R37: =K37*SQRT(5) -> 89.442719 | S37: =Q37/2 -> 34.641016 | T37: =K37*0.5 -> 20
B38: =B23*80 -> 178.88544 | C38: =C23*80 -> 501.3295 | D38: =D23*80 -> 191.49083 | E38: =E23*80 -> 154.91933 | F38: =F23*80 -> 434.16408 | G38: =G23*80 -> 165.83592 | I38: ="1/3" -> 1/3 | J38: =1/3 -> 0.33333333 | K38: =J38*80 -> 26.666667 | L38: =K38*(1+SQRT(5))/2 -> 43.147573 | M38: =K38*(SQRT(5)-1)/2 -> 16.480906 | N38: =L38/2 -> 21.573787 | O38: =M38/2 -> 8.2404532 | P38: =K38*SQRT(2) -> 37.712362 | Q38: =K38*SQRT(3) -> 46.188022 | R38: =K38*SQRT(5) -> 59.628479 | S38: =Q38/2 -> 23.094011 | T38: =K38*0.5 -> 13.333333
I39: ="1/4" -> 1/4 | J39: =1/4 -> 0.25 | K39: =J39*80 -> 20 | L39: =K39*(1+SQRT(5))/2 -> 32.36068 | M39: =K39*(SQRT(5)-1)/2 -> 12.36068 | N39: =L39/2 -> 16.18034 | O39: =M39/2 -> 6.1803399 | P39: =K39*SQRT(2) -> 28.284271 | Q39: =K39*SQRT(3) -> 34.641016 | R39: =K39*SQRT(5) -> 44.72136 | S39: =Q39/2 -> 17.320508 | T39: =K39*0.5 -> 10
I40: ="1/5" -> 1/5 | J40: =1/5 -> 0.2 | K40: =J40*80 -> 16 | L40: =K40*(1+SQRT(5))/2 -> 25.888544 | M40: =K40*(SQRT(5)-1)/2 -> 9.8885438 | N40: =L40/2 -> 12.944272 | O40: =M40/2 -> 4.9442719 | P40: =K40*SQRT(2) -> 22.627417 | Q40: =K40*SQRT(3) -> 27.712813 | R40: =K40*SQRT(5) -> 35.777088 | S40: =Q40/2 -> 13.856406 | T40: =K40*0.5 -> 8
I41: ="1/6" -> 1/6 | J41: =1/6 -> 0.16666667 | K41: =J41*80 -> 13.333333 | L41: =K41*(1+SQRT(5))/2 -> 21.573787 | M41: =K41*(SQRT(5)-1)/2 -> 8.2404532 | N41: =L41/2 -> 10.786893 | O41: =M41/2 -> 4.1202266 | P41: =K41*SQRT(2) -> 18.856181 | Q41: =K41*SQRT(3) -> 23.094011 | R41: =K41*SQRT(5) -> 29.81424 | S41: =Q41/2 -> 11.547005 | T41: =K41*0.5 -> 6.6666667 | X41: 18
I42: ="1/7" -> 1/7 | J42: =1/7 -> 0.14285714 | K42: =J42*80 -> 11.428571 | L42: =K42*(1+SQRT(5))/2 -> 18.491817 | M42: =K42*(SQRT(5)-1)/2 -> 7.0632456 | N42: =L42/2 -> 9.2459085 | O42: =M42/2 -> 3.5316228 | P42: =K42*SQRT(2) -> 16.162441 | Q42: =K42*SQRT(3) -> 19.794866 | R42: =K42*SQRT(5) -> 25.555063 | S42: =Q42/2 -> 9.8974332 | T42: =K42*0.5 -> 5.7142857 | X42: 16.363636
I43: ="1/8" -> 1/8 | J43: =1/8 -> 0.125 | K43: =J43*80 -> 10 | L43: =K43*(1+SQRT(5))/2 -> 16.18034 | M43: =K43*(SQRT(5)-1)/2 -> 6.1803399 | N43: =L43/2 -> 8.0901699 | O43: =M43/2 -> 3.0901699 | P43: =K43*SQRT(2) -> 14.142136 | Q43: =K43*SQRT(3) -> 17.320508 | R43: =K43*SQRT(5) -> 22.36068 | S43: =Q43/2 -> 8.660254 | T43: =K43*0.5 -> 5 | X43: 15
...

Sheet angs
A1: Fraction | B1: ="pi/div rads" -> pi/div rads | C1: div | D1: ="degrees" -> degrees | E1: 135 | F1: 120 | G1: 108 | H1: 90 | I1: 72 | J1: 60 | K1: 45 | L1: 36 | M1: 30 | N1: 25.714286 | O1: 22.5 | P1: ="20.0" -> 20.0 | Q1: 18 | R1: 16.363636 | S1: 15 | T1: 13.846154 | U1: 12.857143 | V1: 12
A2: =3/4 -> 0.75 | B2: =PI()*A2 -> 2.3561945 | C2: =1/A2 -> 1.3333333 | D2: =DEGREES(B2) -> 135 | F2: =F1-135 -> -15 | G2: =G1-135 -> -27 | H2: =H1-135 -> -45 | I2: =I1-135 -> -63 | J2: =J1-135 -> -75 | K2: =K1-135 -> -90 | L2: =L1-135 -> -99 | M2: =M1-135 -> -105 | ... V2: =V1-135 -> -123
A3: =2/3 -> 0.66666667 | B3: =PI()*A3 -> 2.0943951 | C3: =1/A3 -> 1.5 | D3: =DEGREES(B3) -> 120 | E3: =E1-120 -> 15 | G3: =G1-120 -> -12 | H3: =H1-120 -> -30 | I3: =I1-120 -> -48 | J3: =J1-120 -> -60 | K3: =K1-120 -> -75 | L3: =L1-120 -> -84 | M3: =M1-120 -> -90 | N3: =N1-120 -> -94.285714 | ... V3: =V1-120 -> -108
A4: =3/5 -> 0.6 | B4: =PI()*A4 -> 1.8849556 | C4: =1/A4 -> 1.6666667 | D4: =DEGREES(B4) -> 108 | E4: =E1-108 -> 27 | F4: =F1-108 -> 12 | H4: =H1-108 -> -18 | I4: =I1-108 -> -36 | J4: =J1-108 -> -48 | K4: =K1-108 -> -63 | L4: =L1-108 -> -72 | M4: =M1-108 -> -78 | N4: =N1-108 -> -82.285714 | O4: =O1-108 -> -85.5 | ... V4: =V1-108 -> -96
A5: 0.5 | B5: =PI()*A5 -> 1.5707963 | C5: =1/A5 -> 2 | D5: =DEGREES(B5) -> 90 | E5: =E1-90 -> 45 | F5: =F1-90 -> 30 | G5: =G1-90 -> 18 | I5: =I1-90 -> -18 | J5: =J1-90 -> -30 | K5: =K1-90 -> -45 | L5: =L1-90 -> -54 | M5: =M1-90 -> -60 | N5: =N1-90 -> -64.285714 | O5: =O1-90 -> -67.5 | P5: =P1-90 -> -70 | ... V5: =V1-90 -> -78
A6: =2/5 -> 0.4 | B6: =PI()*A6 -> 1.2566371 | C6: =1/A6 -> 2.5 | D6: =DEGREES(B6) -> 72 | E6: =E1-72 -> 63 | F6: =F1-72 -> 48 | G6: =G1-72 -> 36 | H6: =H1-72 -> 18 | J6: =J1-72 -> -12 | K6: =K1-72 -> -27 | L6: =L1-72 -> -36 | M6: =M1-72 -> -42 | N6: =N1-72 -> -46.285714 | O6: =O1-72 -> -49.5 | P6: =P1-72 -> -52 | Q6: =Q1-72 -> -54 | ... V6: =V1-72 -> -60
A7: =1/3 -> 0.33333333 | B7: =PI()*A7 -> 1.0471976 | C7: =1/A7 -> 3 | D7: =DEGREES(B7) -> 60 | E7: =E1-60 -> 75 | F7: =F1-60 -> 60 | G7: =G1-60 -> 48 | H7: =H1-60 -> 30 | I7: =I1-60 -> 12 | K7: =K1-60 -> -15 | L7: =L1-60 -> -24 | M7: =M1-60 -> -30 | N7: =N1-60 -> -34.285714 | O7: =O1-60 -> -37.5 | P7: =P1-60 -> -40 | Q7: =Q1-60 -> -42 | R7: =R1-60 -> -43.636364 | ... V7: =V1-60 -> -48
A8: =1/4 -> 0.25 | B8: =PI()*A8 -> 0.78539816 | C8: =1/A8 -> 4 | D8: =DEGREES(B8) -> 45 | E8: =E1-45 -> 90 | F8: =F1-45 -> 75 | G8: =G1-45 -> 63 | H8: =H1-45 -> 45 | I8: =I1-45 -> 27 | J8: =J1-45 -> 15 | L8: =L1-45 -> -9 | M8: =M1-45 -> -15 | N8: =N1-45 -> -19.285714 | O8: =O1-45 -> -22.5 | P8: =P1-45 -> -25 | Q8: =Q1-45 -> -27 | R8: =R1-45 -> -28.636364 | S8: =S1-45 -> -30 | ... V8: =V1-45 -> -33
A9: =1/5 -> 0.2 | B9: =PI()*A9 -> 0.62831853 | C9: =1/A9 -> 5 | D9: =DEGREES(B9) -> 36 | E9: =E1-36 -> 99 | F9: =F1-36 -> 84 | G9: =G1-36 -> 72 | H9: =H1-36 -> 54 | I9: =I1-36 -> 36 | J9: =J1-36 -> 24 | K9: =K1-36 -> 9 | M9: =M1-36 -> -6 | N9: =N1-36 -> -10.285714 | O9: =O1-36 -> -13.5 | P9: =P1-36 -> -16 | Q9: =Q1-36 -> -18 | R9: =R1-36 -> -19.636364 | S9: =S1-36 -> -21 | T9: =T1-36 -> -22.153846 | ... V9: =V1-36 -> -24
A10: =1/6 -> 0.16666667 | B10: =PI()*A10 -> 0.52359878 | C10: =1/A10 -> 6 | D10: =DEGREES(B10) -> 30 | E10: =E1-30 -> 105 | F10: =F1-30 -> 90 | G10: =G1-30 -> 78 | H10: =H1-30 -> 60 | I10: =I1-30 -> 42 | J10: =J1-30 -> 30 | K10: =K1-30 -> 15 | L10: =L1-30 -> 6 | N10: =N1-30 -> -4.2857143 | O10: =O1-30 -> -7.5 | P10: =P1-30 -> -10 | Q10: =Q1-30 -> -12 | R10: =R1-30 -> -13.636364 | S10: =S1-30 -> -15 | T10: =T1-30 -> -16.153846 | U10: =U1-30 -> -17.142857 | V10: =V1-30 -> -18
A11: =1/7 -> 0.14285714 | B11: =PI()*A11 -> 0.44879895 | C11: =1/A11 -> 7 | D11: =DEGREES(B11) -> 25.714286 | E11: =E1-25.7142857142857 -> 109.28571 | F11: =F1-25.7142857142857 -> 94.285714 | G11: =G1-25.7142857142857 -> 82.285714 | H11: =H1-25.7142857142857 -> 64.285714 | I11: =I1-25.7142857142857 -> 46.285714 | J11: =J1-25.7142857142857 -> 34.285714 | K11: =K1-25.7142857142857 -> 19.285714 | L11: =L1-25.7142857142857 -> 10.285714 | M11: =M1-25.7142857142857 -> 4.2857143 | O11: =O1-25.7142857142857 -> -3.2142857 | P11: =P1-25.7142857142857 -> -5.7142857 | Q11: =Q1-25.7142857142857 -> -7.7142857 | R11: =R1-25.7142857142857 -> -9.3506494 | S11: =S1-25.7142857142857 -> -10.714286 | T11: =T1-25.7142857142857 -> -11.868132 | U11: =U1-25.7142857142857 -> -12.857143 | V11: =V1-25.7142857142857 -> -13.714286
A12: =1/8 -> 0.125 | B12: =PI()*A12 -> 0.39269908 | C12: =1/A12 -> 8 | D12: =DEGREES(B12) -> 22.5 | E12: =E1-22.5 -> 112.5 | F12: =F1-22.5 -> 97.5 | G12: =G1-22.5 -> 85.5 | H12: =H1-22.5 -> 67.5 | I12: =I1-22.5 -> 49.5 | J12: =J1-22.5 -> 37.5 | K12: =K1-22.5 -> 22.5 | L12: =L1-22.5 -> 13.5 | ... N12: =N1-22.5 -> 3.2142857 | P12: =P1-22.5 -> -2.5 | Q12: =Q1-22.5 -> -4.5 | R12: =R1-22.5 -> -6.1363636 | S12: =S1-22.5 -> -7.5 | T12: =T1-22.5 -> -8.6538462 | U12: =U1-22.5 -> -9.6428571 | V12: =V1-22.5 -> -10.5
A13: =1/9 -> 0.11111111 | B13: =PI()*A13 -> 0.34906585 | C13: =1/A13 -> 9 | D13: =DEGREES(B13) -> 20 | E13: =E1-20 -> 115 | F13: =F1-20 -> 100 | G13: =G1-20 -> 88 | H13: =H1-20 -> 70 | I13: =I1-20 -> 52 | J13: =J1-20 -> 40 | K13: =K1-20 -> 25 | L13: =L1-20 -> 16 | ... O13: =O1-20 -> 2.5 | Q13: =Q1-20 -> -2 | R13: =R1-20 -> -3.6363636 | S13: =S1-20 -> -5 | T13: =T1-20 -> -6.1538462 | U13: =U1-20 -> -7.1428571 | V13: =V1-20 -> -8
A14: =1/C14 -> 0.1 | B14: =PI()*A14 -> 0.31415927 | C14: 10 | D14: =DEGREES(B14) -> 18 | E14: =E1-18 -> 117 | F14: =F1-18 -> 102 | G14: =G1-18 -> 90 | H14: =H1-18 -> 72 | I14: =I1-18 -> 54 | J14: =J1-18 -> 42 | K14: =K1-18 -> 27 | L14: =L1-18 -> 18 | ... P14: =P1-18 -> 2 | R14: =R1-18 -> -1.6363636 | S14: =S1-18 -> -3 | T14: =T1-18 -> -4.1538462 | U14: =U1-18 -> -5.1428571 | V14: =V1-18 -> -6
A15: =1/C15 -> 0.090909091 | B15: =PI()*A15 -> 0.28559933 | C15: 11 | D15: =DEGREES(B15) -> 16.363636 | E15: =E1-16.3636363636364 -> 118.63636 | F15: =F1-16.3636363636364 -> 103.63636 | G15: =G1-16.3636363636364 -> 91.636364 | H15: =H1-16.3636363636364 -> 73.636364 | I15: =I1-16.3636363636364 -> 55.636364 | J15: =J1-16.3636363636364 -> 43.636364 | K15: =K1-16.3636363636364 -> 28.636364 | L15: =L1-16.3636363636364 -> 19.636364 | ... Q15: =Q1-16.3636363636364 -> 1.6363636 | S15: =S1-16.3636363636364 -> -1.3636364 | T15: =T1-16.3636363636364 -> -2.5174825 | U15: =U1-16.3636363636364 -> -3.5064935 | V15: =V1-16.3636363636364 -> -4.3636364
A16: =1/C16 -> 0.083333333 | B16: =PI()*A16 -> 0.26179939 | C16: 12 | D16: =DEGREES(B16) -> 15 | E16: =E1-15 -> 120 | F16: =F1-15 -> 105 | G16: =G1-15 -> 93 | H16: =H1-15 -> 75 | I16: =I1-15 -> 57 | J16: =J1-15 -> 45 | K16: =K1-15 -> 30 | L16: =L1-15 -> 21 | ... R16: =R1-15 -> 1.3636364 | T16: =T1-15 -> -1.1538462 | U16: =U1-15 -> -2.1428571 | V16: =V1-15 -> -3
A17: =1/C17 -> 0.076923077 | B17: =PI()*A17 -> 0.24166097 | C17: 13 | D17: =DEGREES(B17) -> 13.846154 | E17: =E1-13.8461538461538 -> 121.15385 | F17: =F1-13.8461538461538 -> 106.15385 | G17: =G1-13.8461538461538 -> 94.153846 | H17: =H1-13.8461538461538 -> 76.153846 | I17: =I1-13.8461538461538 -> 58.153846 | J17: =J1-13.8461538461538 -> 46.153846 | K17: =K1-13.8461538461538 -> 31.153846 | L17: =L1-13.8461538461538 -> 22.153846 | ... S17: =S1-13.8461538461538 -> 1.1538462 | U17: =U1-13.8461538461538 -> -0.98901099 | V17: =V1-13.8461538461538 -> -1.8461538
A18: =1/C18 -> 0.071428571 | B18: =PI()*A18 -> 0.22439948 | C18: 14 | D18: =DEGREES(B18) -> 12.857143 | E18: =E1-12.8571428571429 -> 122.14286 | F18: =F1-12.8571428571429 -> 107.14286 | G18: =G1-12.8571428571429 -> 95.142857 | H18: =H1-12.8571428571429 -> 77.142857 | I18: =I1-12.8571428571429 -> 59.142857 | J18: =J1-12.8571428571429 -> 47.142857 | K18: =K1-12.8571428571429 -> 32.142857 | L18: =L1-12.8571428571429 -> 23.142857 | ... T18: =T1-12.8571428571429 -> 0.98901099 | V18: =V1-12.8571428571429 -> -0.85714286
A19: =1/C19 -> 0.066666667 | B19: =PI()*A19 -> 0.20943951 | C19: 15 | D19: =DEGREES(B19) -> 12 | E19: =E1-12 -> 123 | F19: =F1-12 -> 108 | G19: =G1-12 -> 96 | H19: =H1-12 -> 78 | I19: =I1-12 -> 60 | J19: =J1-12 -> 48 | K19: =K1-12 -> 33 | L19: =L1-12 -> 24 | ... U19: =U1-12 -> 0.85714286
B20: golden angle: | C20: ="2*pi/phi^2" -> 2*pi/phi^2 | D20: 222.5 | E20: =222.5-E1 -> 87.5 | F20: =222.5-F1 -> 102.5 | G20: =222.5-G1 -> 114.5 | H20: =222.5-H1 -> 132.5 | I20: =222.5-I1 -> 150.5 | J20: =222.5-J1 -> 162.5 | K20: =222.5-K1 -> 177.5 | L20: =222.5-L1 -> 186.5 | ... V20: =222.5-V1 -> 210.5
C21: ="2*pi/phi" -> 2*pi/phi | D21: 137.5 | E21: =137.5-E1 -> 2.5 | F21: =137.5-F1 -> 17.5 | G21: =137.5-G1 -> 29.5 | H21: =137.5-H1 -> 47.5 | I21: =137.5-I1 -> 65.5 | J21: =137.5-J1 -> 77.5 | K21: =137.5-K1 -> 92.5 | L21: =137.5-L1 -> 101.5 | ... V21: =137.5-V1 -> 125.5
A23: TRIANGLES
B24: Type | C24: a | D24: b | E24: c | F24: 1.618034
A25: Sides | B25: r2 r3 r5 | C25: =SQRT(2) -> 1.4142136 | D25: =SQRT(3) -> 1.7320508 | E25: =SQRT(5) -> 2.236068 | F25: s | H25: rads/pi | K25: ="pi/rads" -> pi/rads
A26: Angles | C26: =DEGREES(ASIN(C25/E25)) -> 39.23152 | D26: =DEGREES(ASIN(D25/E25)) -> 50.76848 | E26: 90 | F26: a | H26: =RADIANS(C26)/PI() -> 0.21795289 | I26: =RADIANS(D26)/PI() -> 0.28204711 | J26: =RADIANS(E26)/PI() -> 0.5 | K26: =1/H26 -> 4.5881474 | L26: =1/I26 -> 3.545507 | M26: =1/J26 -> 2
B27: 30 60 90 | C27: 1 | D27: =SQRT(3) -> 1.7320508 | E27: 2 | F27: s
C28: =DEGREES(ASIN(C27/E27)) -> 30 | D28: 60 | E28: 90 | F28: a | H28: =RADIANS(C28)/PI() -> 0.16666667 | I28: =RADIANS(D28)/PI() -> 0.33333333 | J28: =RADIANS(E28)/PI() -> 0.5 | K28: =1/H28 -> 6 | L28: =1/I28 -> 3 | M28: =1/J28 -> 2
B29: r2 r2 1 | C29: =SQRT(2) -> 1.4142136 | D29: =SQRT(2) -> 1.4142136 | E29: 1 | F29: s | G29: =5*D29 -> 7.0710678
C30: 45 | D30: 45 | E30: 90 | F30: a | H30: =RADIANS(C30)/PI() -> 0.25 | I30: =RADIANS(D30)/PI() -> 0.25 | J30: =RADIANS(E30)/PI() -> 0.5 | K30: =1/H30 -> 4 | L30: =1/I30 -> 4 | M30: =1/J30 -> 2
B31: ="3 - 4 - 5" -> 3 - 4 - 5 | C31: 3 | D31: 4 | E31: 5 | F31: s
C32: =DEGREES(ASIN(C31/E31)) -> 36.869898 | D32: =DEGREES(ASIN(D31/E31)) -> 53.130102 | E32: 90 | F32: a | H32: =RADIANS(C32)/PI() -> 0.20483276 | I32: =RADIANS(D32)/PI() -> 0.29516724 | J32: =RADIANS(E32)/PI() -> 0.5 | K32: =1/H32 -> 4.8820315 | L32: =1/I32 -> 3.3879099 | M32: =1/J32 -> 2
B33: 1 2 r5 | C33: 1 | D33: 2 | E33: =SQRT(5) -> 2.236068 | F33: s
C34: =DEGREES(ASIN(C33/E33)) -> 26.565051 | D34: =DEGREES(ASIN(D33/E33)) -> 63.434949 | E34: 90 | F34: a | H34: =RADIANS(C34)/PI() -> 0.14758362 | I34: =RADIANS(D34)/PI() -> 0.35241638 | J34: =RADIANS(E34)/PI() -> 0.5 | K34: =1/H34 -> 6.7758198 | L34: =1/I34 -> 2.8375525 | M34: =1/J34 -> 2
B35: 18 72 90 | C35: =E35*SIN(RADIANS(C36)) -> 0.47552826 | D35: 1.618034 | E35: =D35*SIN(RADIANS(D36)) -> 1.5388418 | F35: s | G35: =E35^4 -> 5.607585
C36: 18 | D36: 72 | E36: 90 | F36: a | H36: =RADIANS(C36)/PI() -> 0.1 | I36: =RADIANS(D36)/PI() -> 0.4 | J36: =RADIANS(E36)/PI() -> 0.5 | K36: =1/H36 -> 10 | L36: =1/I36 -> 2.5 | M36: =1/J36 -> 2
B37: 36 54 90 | C37: =E37*SIN(RADIANS(C38)) -> 1.3143278 | D37: 2 | E37: =SQRT(5) -> 2.236068 | F37: s
C38: 36 | D38: 54 | E38: 90 | F38: a | H38: =RADIANS(C38)/PI() -> 0.2 | I38: =RADIANS(D38)/PI() -> 0.3 | J38: =RADIANS(E38)/PI() -> 0.5 | K38: =1/H38 -> 5 | L38: =1/I38 -> 3.3333333 | M38: =1/J38 -> 2
B39: 1 phi phi^2 | C39: 1 | D39: 1.618034 | E39: =1.61803398874989^2 -> 2.618034 | F39: s
C40: =DEGREES(ASIN(1/1.61803398874989)) -> 38.172708 | D40: =DEGREES(ACOS(1/1.61803398874989)) -> 51.827292 | E40: 90 | F40: a | H40: =RADIANS(C40)/PI() -> 0.2120706 | I40: =RADIANS(D40)/PI() -> 0.2879294 | J40: =RADIANS(E40)/PI() -> 0.5 | K40: =1/H40 -> 4.7154109 | L40: =1/I40 -> 3.4730736 | M40: =1/J40 -> 2
A44: 45 90 45 | B44: 72 36 72 | C44: 72 90 18
...

Sheet magicnums
A1: magicnums: | B1: val | C1: frac | D1: feet | E1: =((SQRT(5)+1)/2)^(ROW()-1) -> 1 | F1: =E1*5280 -> 5280 | G1: =((SQRT(5)-1)/2)^(ROW()-1) -> 1 | H1: =5280*G1 -> 5280 | I1: =SQRT(2)*((SQRT(5)+1)/2)^(ROW()-1) -> 1.4142136 | J1: =5280*I1 -> 7467.0476 | K1: =SQRT(2)*((SQRT(5)-1)/2)^(ROW()-1) -> 1.4142136 | L1: =5280*K1 -> 7467.0476
A2: FIp | B2: =(SQRT(5)+1)/2 -> 1.618034 | C2: =B2 -> 1.618034 | D2: =B2*5280 -> 8543.2195 | E2: =((SQRT(5)+1)/2)^(ROW()-1) -> 1.618034 | F2: =E2*5280 -> 8543.2195 | G2: =((SQRT(5)-1)/2)^(ROW()-1) -> 0.61803399 | H2: =5280*G2 -> 3263.2195 | I2: =SQRT(2)*((SQRT(5)+1)/2)^(ROW()-1) -> 2.2882456 | J2: =5280*I2 -> 12081.937 | K2: =SQRT(2)*((SQRT(5)-1)/2)^(ROW()-1) -> 0.87403205 | L2: =5280*K2 -> 4614.8892
A3: FIm | B3: =(SQRT(5)-1)/2 -> 0.61803399 | C3: =B3 -> 0.61803399 | D3: =B3*5280 -> 3263.2195 | E3: =((SQRT(5)+1)/2)^(ROW()-1) -> 2.618034 | F3: =E3*5280 -> 13823.219 | G3: =((SQRT(5)-1)/2)^(ROW()-1) -> 0.38196601 | H3: =5280*G3 -> 2016.7805 | I3: =SQRT(2)*((SQRT(5)+1)/2)^(ROW()-1) -> 3.7024592 | J3: =5280*I3 -> 19548.984 | K3: =SQRT(2)*((SQRT(5)-1)/2)^(ROW()-1) -> 0.54018151 | L3: =5280*K3 -> 2852.1584
A4: R2 | B4: =SQRT(2) -> 1.4142136 | C4: =B4 -> 1.4142136 | D4: =B4*5280 -> 7467.0476 | E4: =((SQRT(5)+1)/2)^(ROW()-1) -> 4.236068 | F4: =E4*5280 -> 22366.439 | G4: =((SQRT(5)-1)/2)^(ROW()-1) -> 0.23606798 | H4: =5280*G4 -> 1246.4389 | I4: =SQRT(2)*((SQRT(5)+1)/2)^(ROW()-1) -> 5.9907048 | J4: =5280*I4 -> 31630.921 | K4: =SQRT(2)*((SQRT(5)-1)/2)^(ROW()-1) -> 0.33385054 | L4: =5280*K4 -> 1762.7308
A5: 1/R2 | B5: =1/SQRT(2) -> 0.70710678 | C5: =B5 -> 0.70710678 | D5: =B5*5280 -> 3733.5238 | E5: =((SQRT(5)+1)/2)^(ROW()-1) -> 6.854102 | F5: =E5*5280 -> 36189.658 | G5: =((SQRT(5)-1)/2)^(ROW()-1) -> 0.14589803 | H5: =5280*G5 -> 770.34162 | I5: =SQRT(2)*((SQRT(5)+1)/2)^(ROW()-1) -> 9.693164 | J5: =5280*I5 -> 51179.906 | K5: =SQRT(2)*((SQRT(5)-1)/2)^(ROW()-1) -> 0.20633098 | L5: =5280*K5 -> 1089.4276
A6: R3 | B6: =SQRT(3) -> 1.7320508 | C6: =B6 -> 1.7320508 | D6: =B6*5280 -> 9145.2283 | E6: =((SQRT(5)+1)/2)^(ROW()-1) -> 11.09017 | F6: =E6*5280 -> 58556.097 | G6: =((SQRT(5)-1)/2)^(ROW()-1) -> 0.090169944 | H6: =5280*G6 -> 476.0973 | I6: =SQRT(2)*((SQRT(5)+1)/2)^(ROW()-1) -> 15.683869 | J6: =5280*I6 -> 82810.827 | K6: =SQRT(2)*((SQRT(5)-1)/2)^(ROW()-1) -> 0.12751956 | L6: =5280*K6 -> 673.30326
A7: R3/2 | B7: =SQRT(3)/2 -> 0.8660254 | C7: =B7 -> 0.8660254 | D7: =B7*5280 -> 4572.6141 | E7: =((SQRT(5)+1)/2)^(ROW()-1) -> 17.944272 | F7: =E7*5280 -> 94745.756 | G7: =((SQRT(5)-1)/2)^(ROW()-1) -> 0.05572809 | H7: =5280*G7 -> 294.24432 | I7: =SQRT(2)*((SQRT(5)+1)/2)^(ROW()-1) -> 25.377033 | J7: =5280*I7 -> 133990.73 | K7: =SQRT(2)*((SQRT(5)-1)/2)^(ROW()-1) -> 0.078811421 | L7: =5280*K7 -> 416.1243
A8: FIp^2 | B8: 2.618034 | C8: =B8 -> 2.618034 | D8: =B8*5280 -> 13823.219 | E8: =((SQRT(5)+1)/2)^(ROW()-1) -> 29.034442 | F8: =E8*5280 -> 153301.85 | G8: =((SQRT(5)-1)/2)^(ROW()-1) -> 0.034441854 | H8: =5280*G8 -> 181.85299 | I8: =SQRT(2)*((SQRT(5)+1)/2)^(ROW()-1) -> 41.060901 | J8: =5280*I8 -> 216801.56 | K8: =SQRT(2)*((SQRT(5)-1)/2)^(ROW()-1) -> 0.048708137 | L8: =5280*K8 -> 257.17896
A9: FIpR2 | B9: 2.2882456 | C9: =B9 -> 2.2882456 | D9: =B9*5280 -> 12081.937 | E9: =((SQRT(5)+1)/2)^(ROW()-1) -> 46.978714 | F9: =E9*5280 -> 248047.61 | G9: =((SQRT(5)-1)/2)^(ROW()-1) -> 0.021286236 | H9: =5280*G9 -> 112.39133 | K9: =SQRT(2)*((SQRT(5)-1)/2)^(ROW()-1) -> 0.030103284 | L9: =5280*K9 -> 158.94534
A10: FIp/R2 | B10: 1.1441228 | C10: =B10 -> 1.1441228 | D10: =B10*5280 -> 6040.9684 | G10: =((SQRT(5)-1)/2)^(ROW()-1) -> 0.013155617 | H10: =5280*G10 -> 69.46166 | K10: =SQRT(2)*((SQRT(5)-1)/2)^(ROW()-1) -> 0.018604853 | L10: =5280*K10 -> 98.233622
A11: FIp*R3 | B11: 2.8025171 | C11: =B11 -> 2.8025171 | D11: =B11*5280 -> 14797.29 | G11: =((SQRT(5)-1)/2)^(ROW()-1) -> 0.0081306188 | H11: =5280*G11 -> 42.929667 | K11: =SQRT(2)*((SQRT(5)-1)/2)^(ROW()-1) -> 0.011498431 | L11: =5280*K11 -> 60.711717
A12: Fip*R3*2 | B12: =B11*2 -> 5.6050342 | C12: =B12 -> 5.6050342 | D12: =B12*5280 -> 29594.58 | G12: =((SQRT(5)-1)/2)^(ROW()-1) -> 0.0050249987 | H12: =5280*G12 -> 26.531993 | K12: =SQRT(2)*((SQRT(5)-1)/2)^(ROW()-1) -> 0.0071064214 | L12: =5280*K12 -> 37.521905
A13: FIp*R3/2 | B13: 1.4012585 | C13: =B13 -> 1.4012585 | D13: =B13*5280 -> 7398.6451 | G13: =((SQRT(5)-1)/2)^(ROW()-1) -> 0.00310562 | H13: =5280*G13 -> 16.397674 | K13: =SQRT(2)*((SQRT(5)-1)/2)^(ROW()-1) -> 0.0043920099 | L13: =5280*K13 -> 23.189813
A14: FIm^2 | B14: 0.38196601 | C14: =B14 -> 0.38196601 | D14: =B14*5280 -> 2016.7805 | G14: =((SQRT(5)-1)/2)^(ROW()-1) -> 0.0019193787 | H14: =5280*G14 -> 10.13432 | K14: =SQRT(2)*((SQRT(5)-1)/2)^(ROW()-1) -> 0.0027144114 | L14: =5280*K14 -> 14.332092
A15: FImR2 | B15: 0.87403205 | C15: =B15 -> 0.87403205 | D15: =B15*5280 -> 4614.8892 | G15: =((SQRT(5)-1)/2)^(ROW()-1) -> 0.0011862413 | H15: =5280*G15 -> 6.263354 | K15: =SQRT(2)*((SQRT(5)-1)/2)^(ROW()-1) -> 0.0016775985 | L15: =5280*K15 -> 8.8577202
A16: FIm/R2 | B16: 0.43701602 | C16: =B16 -> 0.43701602 | D16: =B16*5280 -> 2307.4446 | G16: =((SQRT(5)-1)/2)^(ROW()-1) -> 0.00073313744 | H16: =5280*G16 -> 3.8709657 | K16: =SQRT(2)*((SQRT(5)-1)/2)^(ROW()-1) -> 0.0010368129 | L16: =5280*K16 -> 5.4743721
A17: FIm*R3 | B17: 1.0704663 | C17: =B17 -> 1.0704663 | D17: =B17*5280 -> 5652.0619
A18: FIm*R3/2 | B18: 0.53523313 | C18: =B18 -> 0.53523313 | D18: =B18*5280 -> 2826.031

Sheet notable
A1: DISTANCE | L1: ANGLES
A2: 5 | B2: PEN
A3: 5.605 | B3: C AN | C3: PEN S | D3: PEN PO | E3: 2*phi*rad3 | L3: 108 | M3: an.C.s
A4: 6 | B4: N PO | L4: 72 | M4: n.CAP.key
A5: 6.5 | B5: KEY W | C5: KEY RC | D5: C RC | L5: 60 | M5: an.PO.s
A6: 7.1 | B6: CAP RC | C6: KEY S | D6: CAP S | E6: C N | F6: C W | G6: C S | H6: C E | I6: NO 7.071 | L6: 54 | M6: an.S.po
A7: 7.5 | B7: N AN | L7: 18 | M7: c.PO.pen
A8: 8 | B8: PEN E | C8: PEN RC
A9: 8.66 | B9: PEN N
A11: =SQRT(2) -> 1.4142136 | B11: M Cap | C11: 89
A13: CAP: | B13: M,K,J,W,C
A15: R (river): | B15: K30, AN45
B31: phi+ | C31: phi- | D31: ="/2" -> /2 | E31: phi+/2 | F31: phi-/2
A32: 5.600729 | B32: ='[1]special nums'!C20*5.60072901003635 -> 9.0621699 | C32: ='[1]special nums'!D20*5.60072901003635 -> 3.4614409 | D32: ='[1]special nums'!E20*5.60072901003635 -> 2.8003645 | E32: ='[1]special nums'!F20*5.60072901003635 -> 4.531085 | F32: ='[1]special nums'!G20*5.60072901003635 -> 1.7307204
B33: ='[1]special nums'!C22*5.60072901003635 -> 15.696139 | C33: ='[1]special nums'!D22*5.60072901003635 -> 5.9953915 | D33: ='[1]special nums'!E22*5.60072901003635 -> 4.8503736 | E33: ='[1]special nums'!F22*5.60072901003635 -> 7.8480693 | F33: ='[1]special nums'!G22*5.60072901003635 -> 2.9976957
B34: ='[1]special nums'!C21*5.60072901003635 -> 12.815844 | C34: ='[1]special nums'!D21*5.60072901003635 -> 4.8952167 | D34: ='[1]special nums'!E21*5.60072901003635 -> 3.9603135 | E34: ='[1]special nums'!F21*5.60072901003635 -> 6.4079218 | F34: ='[1]special nums'!G21*5.60072901003635 -> 2.4476083
A35: rad3 = | B35: phi*rad3 =
A36: =SQRT(3) -> 1.7320508 | B36: ='[1]special nums'!C20*SQRT(3) -> 2.8025171 | C36: ='[1]special nums'!D20*SQRT(3) -> 1.0704663 | D36: ='[1]special nums'!E20*SQRT(3) -> 0.8660254 | E36: ='[1]special nums'!F20*SQRT(3) -> 1.4012585 | F36: ='[1]special nums'!G20*SQRT(3) -> 0.53523313
B37: ='[1]special nums'!C22*SQRT(3) -> 4.854102 | C37: ='[1]special nums'!D22*SQRT(3) -> 1.854102 | D37: ='[1]special nums'!E22*SQRT(3) -> 1.5 | E37: ='[1]special nums'!F22*SQRT(3) -> 2.427051 | F37: ='[1]special nums'!G22*SQRT(3) -> 0.92705098
B38: ='[1]special nums'!C21*SQRT(3) -> 3.9633577 | C38: ='[1]special nums'!D21*SQRT(3) -> 1.5138679 | D38: ='[1]special nums'!E21*SQRT(3) -> 1.2247449 | E38: ='[1]special nums'!F21*SQRT(3) -> 1.9816788 | F38: ='[1]special nums'!G21*SQRT(3) -> 0.75693396
A39: ="2*phi*rad3 =" -> 2*phi*rad3 =
A40: =B36*2 -> 5.6050342 | B40: ='[1]special nums'!C20*5.605 -> 9.0690805 | C40: ='[1]special nums'!D20*5.605 -> 3.4640805 | D40: ='[1]special nums'!E20*5.605 -> 2.8025 | E40: ='[1]special nums'!F20*5.605 -> 4.5345403 | F40: ='[1]special nums'!G20*5.605 -> 1.7320403
A41: =5.605*SQRT(3) -> 9.7081448 | B41: ='[1]special nums'!C22*5.605 -> 15.708108 | C41: ='[1]special nums'!D22*5.605 -> 5.9999634 | D41: ='[1]special nums'!E22*5.605 -> 4.8540724 | E41: ='[1]special nums'!F22*5.605 -> 7.8540541 | F41: ='[1]special nums'!G22*5.605 -> 2.9999817
A42: =5.605*SQRT(2) -> 7.926667 | B42: ='[1]special nums'!C21*5.605 -> 12.825617 | C42: ='[1]special nums'!D21*5.605 -> 4.8989496 | D42: ='[1]special nums'!E21*5.605 -> 3.9633335 | E42: ='[1]special nums'!F21*5.605 -> 6.4128083 | F42: ='[1]special nums'!G21*5.605 -> 2.4494748
A44: =2880/5280 -> 0.54545455 | B44: ='[1]special nums'!C20*2880/5280 -> 0.88256399 | C44: ='[1]special nums'!D20*2880/5280 -> 0.33710945 | D44: ='[1]special nums'!E20*2880/5280 -> 0.27272727 | E44: ='[1]special nums'!F20*2880/5280 -> 0.441282 | F44: ='[1]special nums'!G20*2880/5280 -> 0.16855472
B45: ='[1]special nums'!C22*2880/5280 -> 1.5286457 | C45: ='[1]special nums'!D22*2880/5280 -> 0.58389069 | D45: ='[1]special nums'!E22*2880/5280 -> 0.47237749 | E45: ='[1]special nums'!F22*2880/5280 -> 0.76432284 | F45: ='[1]special nums'!G22*2880/5280 -> 0.29194535
